<?xml version="1.0"?>
<robot name="simple_arm">
	<link name="base_link">
		<visual>
			<geometry>
				<box size="0.1 0.1 0.1"/>
			</geometry>
		</visual>
	</link>

	<link name="link_1">
		<visual>
			<geometry>
				<box size="0.5 0.1 0.1"/>
			</geometry>
		</visual>
	</link>

	<link name="link_2">
		<visual>
			<geometry>
				<box size="0.5 0.1 0.1"/>
			</geometry>
		</visual>
	</link>

	<joint name="joint_1" type="revolute">
		<parent link="base_link"/>
		<child link="link_1"/>
		<origin xyz="0 0 0.05" rpy="0 0 0"/>
		<axis xyz="0 0 1"/>
		<limit lower="-3.14" upper="3.14" effort="10" velocity="1.0"/>
	</joint>

	<joint name="joint_2" type="revolute">
		<parent link="link_1"/>
		<child link="link_2"/>
		<origin xyz="0.5 0 0" rpy="0 0 0"/>
		<axis xyz="0 1 0"/>
		<limit lower="-3.14" upper="3.14" effort="10" velocity="1.0"/>
	</joint>
</robot>